# テスト修正指示

GitHubのテストが通っていないので、修正を行う。

## 結果

```plaintext
pytest tests/ --cov=app --cov-report=xml --cov-report=term-missing --cov-fail-under=80
  shell: /usr/bin/bash -e {0}
  env:
    pythonLocation: /opt/hostedtoolcache/Python/3.11.13/x64
    PKG_CONFIG_PATH: /opt/hostedtoolcache/Python/3.11.13/x64/lib/pkgconfig
    Python_ROOT_DIR: /opt/hostedtoolcache/Python/3.11.13/x64
    Python2_ROOT_DIR: /opt/hostedtoolcache/Python/3.11.13/x64
    Python3_ROOT_DIR: /opt/hostedtoolcache/Python/3.11.13/x64
    LD_LIBRARY_PATH: /opt/hostedtoolcache/Python/3.11.13/x64/lib
    ENVIRONMENT: test
============================= test session starts ==============================
platform linux -- Python 3.11.13, pytest-8.4.1, pluggy-1.6.0
rootdir: /home/runner/work/spec_rag/spec_rag
configfile: pyproject.toml
plugins: cov-6.2.1, devtools-0.12.2, asyncio-1.1.0, anyio-4.9.0
asyncio: mode=Mode.AUTO, asyncio_default_fixture_loop_scope=function, asyncio_default_test_loop_scope=function
collected 706 items / 3 errors

==================================== ERRORS ====================================
________________ ERROR collecting tests/test_embedding_tasks.py ________________
tests/test_embedding_tasks.py:8: in <module>
    from app.services.embedding_tasks import (
app/services/embedding_tasks.py:151: in <module>
    celery_app = _create_celery_app()
                 ^^^^^^^^^^^^^^^^^^^^
app/services/embedding_tasks.py:127: in _create_celery_app
    app = MockCelery()
          ^^^^^^^^^^
E   NameError: name 'MockCelery' is not defined
_______________ ERROR collecting tests/test_redis_integration.py _______________
tests/test_redis_integration.py:10: in <module>
    from app.services.embedding_tasks import (
app/services/embedding_tasks.py:151: in <module>
    celery_app = _create_celery_app()
                 ^^^^^^^^^^^^^^^^^^^^
app/services/embedding_tasks.py:127: in _create_celery_app
    app = MockCelery()
          ^^^^^^^^^^
E   NameError: name 'MockCelery' is not defined
____________ ERROR collecting tests/test_redis_integration_fixed.py ____________
tests/test_redis_integration_fixed.py:10: in <module>
    from app.services.embedding_tasks import (
app/services/embedding_tasks.py:151: in <module>
    celery_app = _create_celery_app()
                 ^^^^^^^^^^^^^^^^^^^^
app/services/embedding_tasks.py:127: in _create_celery_app
    app = MockCelery()
          ^^^^^^^^^^
E   NameError: name 'MockCelery' is not defined
=============================== warnings summary ===============================
../../../../../opt/hostedtoolcache/Python/3.11.13/x64/lib/python3.11/site-packages/pydantic/_internal/_fields.py:132
  /opt/hostedtoolcache/Python/3.11.13/x64/lib/python3.11/site-packages/pydantic/_internal/_fields.py:132: UserWarning: Field "model_name" in EmbeddingConfig has conflict with protected namespace "model_".

  You may be able to resolve this warning by setting `model_config['protected_namespaces'] = ()`.
    warnings.warn(

-- Docs: https://docs.pytest.org/en/stable/how-to/capture-warnings.html
=========================== short test summary info ============================
ERROR tests/test_embedding_tasks.py - NameError: name 'MockCelery' is not defined
ERROR tests/test_redis_integration.py - NameError: name 'MockCelery' is not defined
ERROR tests/test_redis_integration_fixed.py - NameError: name 'MockCelery' is not defined
!!!!!!!!!!!!!!!!!!! Interrupted: 3 errors during collection !!!!!!!!!!!!!!!!!!!!
======================== 1 warning, 3 errors in 12.60s =========================
Error: Process completed with exit code 2.
```
